ERROR 2023-09-13 22:31:52,605 django.request Thread-1 (process_request_thread) 11704 log log.py 241 django.request log_response 8344 Internal Server Error: /balances
Traceback (most recent call last):
  File "C:\Users\Admin\Documents\Banxware\balances-and-transactions-api\venv\Lib\site-packages\django\core\handlers\exception.py", line 55, in inner
    response = get_response(request)
               ^^^^^^^^^^^^^^^^^^^^^
  File "C:\Users\Admin\Documents\Banxware\balances-and-transactions-api\venv\Lib\site-packages\django\core\handlers\base.py", line 197, in _get_response
    response = wrapped_callback(request, *callback_args, **callback_kwargs)
               ^^^^^^^^^^^^^^^^^^^^^^^^^^^^^^^^^^^^^^^^^^^^^^^^^^^^^^^^^^^^
  File "C:\Users\Admin\Documents\Banxware\balances-and-transactions-api\venv\Lib\site-packages\django\views\decorators\csrf.py", line 56, in wrapper_view
    return view_func(*args, **kwargs)
           ^^^^^^^^^^^^^^^^^^^^^^^^^^
  File "C:\Users\Admin\Documents\Banxware\balances-and-transactions-api\venv\Lib\site-packages\django\views\generic\base.py", line 104, in view
    return self.dispatch(request, *args, **kwargs)
           ^^^^^^^^^^^^^^^^^^^^^^^^^^^^^^^^^^^^^^^
  File "C:\Users\Admin\Documents\Banxware\balances-and-transactions-api\venv\Lib\site-packages\rest_framework\views.py", line 509, in dispatch
    response = self.handle_exception(exc)
               ^^^^^^^^^^^^^^^^^^^^^^^^^^
  File "C:\Users\Admin\Documents\Banxware\balances-and-transactions-api\venv\Lib\site-packages\rest_framework\views.py", line 469, in handle_exception
    self.raise_uncaught_exception(exc)
  File "C:\Users\Admin\Documents\Banxware\balances-and-transactions-api\venv\Lib\site-packages\rest_framework\views.py", line 480, in raise_uncaught_exception
    raise exc
  File "C:\Users\Admin\Documents\Banxware\balances-and-transactions-api\venv\Lib\site-packages\rest_framework\views.py", line 506, in dispatch
    response = handler(request, *args, **kwargs)
               ^^^^^^^^^^^^^^^^^^^^^^^^^^^^^^^^^
  File "C:\Users\Admin\Documents\Banxware\balances-and-transactions-api\venv\Lib\site-packages\rest_framework\generics.py", line 199, in get
    return self.list(request, *args, **kwargs)
           ^^^^^^^^^^^^^^^^^^^^^^^^^^^^^^^^^^^
  File "C:\Users\Admin\Documents\Banxware\balances-and-transactions-api\venv\Lib\site-packages\rest_framework\mixins.py", line 45, in list
    serializer = self.get_serializer(queryset, many=True)
                 ^^^^^^^^^^^^^^^^^^^^^^^^^^^^^^^^^^^^^^^^
  File "C:\Users\Admin\Documents\Banxware\balances-and-transactions-api\venv\Lib\site-packages\rest_framework\generics.py", line 108, in get_serializer
    serializer_class = self.get_serializer_class()
                       ^^^^^^^^^^^^^^^^^^^^^^^^^^^
  File "C:\Users\Admin\Documents\Banxware\balances-and-transactions-api\venv\Lib\site-packages\rest_framework\generics.py", line 122, in get_serializer_class
    assert self.serializer_class is not None, (
           ^^^^^^^^^^^^^^^^^^^^^^^^^^^^^^^^^
AssertionError: 'BalancesList' should either include a `serializer_class` attribute, or override the `get_serializer_class()` method.
ERROR 2023-09-13 22:31:52,614 django.server Thread-1 (process_request_thread) 11704 basehttp basehttp.py 212 django.server log_message 8344 "GET /balances HTTP/1.1" 500 113933
ERROR 2023-09-13 22:34:50,452 django.request Thread-1 (process_request_thread) 20524 log log.py 241 django.request log_response 17484 Internal Server Error: /balances
Traceback (most recent call last):
  File "C:\Users\Admin\Documents\Banxware\balances-and-transactions-api\venv\Lib\site-packages\django\core\handlers\exception.py", line 55, in inner
    response = get_response(request)
               ^^^^^^^^^^^^^^^^^^^^^
  File "C:\Users\Admin\Documents\Banxware\balances-and-transactions-api\venv\Lib\site-packages\django\utils\deprecation.py", line 136, in __call__
    response = self.process_response(request, response)
               ^^^^^^^^^^^^^^^^^^^^^^^^^^^^^^^^^^^^^^^^
  File "C:\Users\Admin\Documents\Banxware\balances-and-transactions-api\venv\Lib\site-packages\django\middleware\clickjacking.py", line 34, in process_response
    response.headers["X-Frame-Options"] = self.get_xframe_options_value(
    ^^^^^^^^^^^^^^^^
AttributeError: 'dict' object has no attribute 'headers'
ERROR 2023-09-13 22:34:50,457 django.server Thread-1 (process_request_thread) 20524 basehttp basehttp.py 212 django.server log_message 17484 "GET /balances HTTP/1.1" 500 72224
WARNING 2023-09-13 22:39:38,785 django.request Thread-1 (process_request_thread) 17508 log log.py 241 django.request log_response 9492 Not Found: /swagger/json/
WARNING 2023-09-13 22:39:38,787 django.server Thread-1 (process_request_thread) 17508 basehttp basehttp.py 212 django.server log_message 9492 "GET /swagger/json/ HTTP/1.1" 404 2748
WARNING 2023-09-13 22:39:44,734 django.request Thread-1 (process_request_thread) 17508 log log.py 241 django.request log_response 9492 Not Found: /swaggerjson/
WARNING 2023-09-13 22:39:44,735 django.server Thread-1 (process_request_thread) 17508 basehttp basehttp.py 212 django.server log_message 9492 "GET /swaggerjson/ HTTP/1.1" 404 23
WARNING 2023-09-13 22:39:45,810 django.request Thread-1 (process_request_thread) 17508 log log.py 241 django.request log_response 9492 Not Found: /swaggerjson/
WARNING 2023-09-13 22:39:45,812 django.server Thread-1 (process_request_thread) 17508 basehttp basehttp.py 212 django.server log_message 9492 "GET /swaggerjson/ HTTP/1.1" 404 23
WARNING 2023-09-13 22:39:49,424 django.request Thread-1 (process_request_thread) 17508 log log.py 241 django.request log_response 9492 Not Found: /swagger<json>/
WARNING 2023-09-13 22:39:49,425 django.server Thread-1 (process_request_thread) 17508 basehttp basehttp.py 212 django.server log_message 9492 "GET /swagger%3Cjson%3E/ HTTP/1.1" 404 23
WARNING 2023-09-13 22:39:50,524 django.request Thread-1 (process_request_thread) 17508 log log.py 241 django.request log_response 9492 Not Found: /swagger<json>/
WARNING 2023-09-13 22:39:50,526 django.server Thread-1 (process_request_thread) 17508 basehttp basehttp.py 212 django.server log_message 9492 "GET /swagger%3Cjson%3E/ HTTP/1.1" 404 23
WARNING 2023-09-13 22:39:55,560 django.request Thread-1 (process_request_thread) 17508 log log.py 241 django.request log_response 9492 Not Found: /swagger<json>/
WARNING 2023-09-13 22:39:55,562 django.server Thread-1 (process_request_thread) 17508 basehttp basehttp.py 212 django.server log_message 9492 "GET /swagger%3Cjson%3E/ HTTP/1.1" 404 23
ERROR 2023-09-13 22:47:04,442 django.request Thread-1 (process_request_thread) 11336 log log.py 241 django.request log_response 17500 Internal Server Error: /balances
Traceback (most recent call last):
  File "C:\Users\Admin\Documents\Banxware\balances-and-transactions-api\venv\Lib\site-packages\django\core\handlers\exception.py", line 55, in inner
    response = get_response(request)
               ^^^^^^^^^^^^^^^^^^^^^
  File "C:\Users\Admin\Documents\Banxware\balances-and-transactions-api\venv\Lib\site-packages\django\core\handlers\base.py", line 197, in _get_response
    response = wrapped_callback(request, *callback_args, **callback_kwargs)
               ^^^^^^^^^^^^^^^^^^^^^^^^^^^^^^^^^^^^^^^^^^^^^^^^^^^^^^^^^^^^
  File "C:\Users\Admin\Documents\Banxware\balances-and-transactions-api\venv\Lib\site-packages\django\views\decorators\csrf.py", line 56, in wrapper_view
    return view_func(*args, **kwargs)
           ^^^^^^^^^^^^^^^^^^^^^^^^^^
  File "C:\Users\Admin\Documents\Banxware\balances-and-transactions-api\venv\Lib\site-packages\django\views\generic\base.py", line 104, in view
    return self.dispatch(request, *args, **kwargs)
           ^^^^^^^^^^^^^^^^^^^^^^^^^^^^^^^^^^^^^^^
  File "C:\Users\Admin\Documents\Banxware\balances-and-transactions-api\venv\Lib\site-packages\rest_framework\views.py", line 509, in dispatch
    response = self.handle_exception(exc)
               ^^^^^^^^^^^^^^^^^^^^^^^^^^
  File "C:\Users\Admin\Documents\Banxware\balances-and-transactions-api\venv\Lib\site-packages\rest_framework\views.py", line 469, in handle_exception
    self.raise_uncaught_exception(exc)
  File "C:\Users\Admin\Documents\Banxware\balances-and-transactions-api\venv\Lib\site-packages\rest_framework\views.py", line 480, in raise_uncaught_exception
    raise exc
  File "C:\Users\Admin\Documents\Banxware\balances-and-transactions-api\venv\Lib\site-packages\rest_framework\views.py", line 506, in dispatch
    response = handler(request, *args, **kwargs)
               ^^^^^^^^^^^^^^^^^^^^^^^^^^^^^^^^^
  File "C:\Users\Admin\Documents\Banxware\balances-and-transactions-api\venv\Lib\site-packages\rest_framework\generics.py", line 199, in get
    return self.list(request, *args, **kwargs)
           ^^^^^^^^^^^^^^^^^^^^^^^^^^^^^^^^^^^
  File "C:\Users\Admin\Documents\Banxware\balances-and-transactions-api\venv\Lib\site-packages\rest_framework\mixins.py", line 38, in list
    queryset = self.filter_queryset(self.get_queryset())
                                    ^^^^^^^^^^^^^^^^^^^
  File "C:\Users\Admin\Documents\Banxware\balances-and-transactions-api\historical_balances\historical_balances\hbalances\views.py", line 20, in get_queryset
    return JsonResponse(balances_serializer)
           ^^^^^^^^^^^^^^^^^^^^^^^^^^^^^^^^^
  File "C:\Users\Admin\Documents\Banxware\balances-and-transactions-api\venv\Lib\site-packages\django\http\response.py", line 724, in __init__
    raise TypeError(
TypeError: In order to allow non-dict objects to be serialized set the safe parameter to False.
ERROR 2023-09-13 22:47:04,450 django.server Thread-1 (process_request_thread) 11336 basehttp basehttp.py 212 django.server log_message 17500 "GET /balances HTTP/1.1" 500 115664
ERROR 2023-09-13 22:47:14,279 django.request Thread-1 (process_request_thread) 6772 log log.py 241 django.request log_response 5940 Internal Server Error: /balances
Traceback (most recent call last):
  File "C:\Users\Admin\Documents\Banxware\balances-and-transactions-api\venv\Lib\site-packages\django\core\handlers\exception.py", line 55, in inner
    response = get_response(request)
               ^^^^^^^^^^^^^^^^^^^^^
  File "C:\Users\Admin\Documents\Banxware\balances-and-transactions-api\venv\Lib\site-packages\django\core\handlers\base.py", line 197, in _get_response
    response = wrapped_callback(request, *callback_args, **callback_kwargs)
               ^^^^^^^^^^^^^^^^^^^^^^^^^^^^^^^^^^^^^^^^^^^^^^^^^^^^^^^^^^^^
  File "C:\Users\Admin\Documents\Banxware\balances-and-transactions-api\venv\Lib\site-packages\django\views\decorators\csrf.py", line 56, in wrapper_view
    return view_func(*args, **kwargs)
           ^^^^^^^^^^^^^^^^^^^^^^^^^^
  File "C:\Users\Admin\Documents\Banxware\balances-and-transactions-api\venv\Lib\site-packages\django\views\generic\base.py", line 104, in view
    return self.dispatch(request, *args, **kwargs)
           ^^^^^^^^^^^^^^^^^^^^^^^^^^^^^^^^^^^^^^^
  File "C:\Users\Admin\Documents\Banxware\balances-and-transactions-api\venv\Lib\site-packages\rest_framework\views.py", line 509, in dispatch
    response = self.handle_exception(exc)
               ^^^^^^^^^^^^^^^^^^^^^^^^^^
  File "C:\Users\Admin\Documents\Banxware\balances-and-transactions-api\venv\Lib\site-packages\rest_framework\views.py", line 469, in handle_exception
    self.raise_uncaught_exception(exc)
  File "C:\Users\Admin\Documents\Banxware\balances-and-transactions-api\venv\Lib\site-packages\rest_framework\views.py", line 480, in raise_uncaught_exception
    raise exc
  File "C:\Users\Admin\Documents\Banxware\balances-and-transactions-api\venv\Lib\site-packages\rest_framework\views.py", line 506, in dispatch
    response = handler(request, *args, **kwargs)
               ^^^^^^^^^^^^^^^^^^^^^^^^^^^^^^^^^
  File "C:\Users\Admin\Documents\Banxware\balances-and-transactions-api\venv\Lib\site-packages\rest_framework\generics.py", line 199, in get
    return self.list(request, *args, **kwargs)
           ^^^^^^^^^^^^^^^^^^^^^^^^^^^^^^^^^^^
  File "C:\Users\Admin\Documents\Banxware\balances-and-transactions-api\venv\Lib\site-packages\rest_framework\mixins.py", line 38, in list
    queryset = self.filter_queryset(self.get_queryset())
                                    ^^^^^^^^^^^^^^^^^^^
  File "C:\Users\Admin\Documents\Banxware\balances-and-transactions-api\historical_balances\historical_balances\hbalances\views.py", line 20, in get_queryset
    return JsonResponse(balances_serializer, safe=False)
           ^^^^^^^^^^^^^^^^^^^^^^^^^^^^^^^^^^^^^^^^^^^^^
  File "C:\Users\Admin\Documents\Banxware\balances-and-transactions-api\venv\Lib\site-packages\django\http\response.py", line 731, in __init__
    data = json.dumps(data, cls=encoder, **json_dumps_params)
           ^^^^^^^^^^^^^^^^^^^^^^^^^^^^^^^^^^^^^^^^^^^^^^^^^^
  File "C:\Users\Admin\AppData\Local\Programs\Python\Python311\Lib\json\__init__.py", line 238, in dumps
    **kw).encode(obj)
          ^^^^^^^^^^^
  File "C:\Users\Admin\AppData\Local\Programs\Python\Python311\Lib\json\encoder.py", line 200, in encode
    chunks = self.iterencode(o, _one_shot=True)
             ^^^^^^^^^^^^^^^^^^^^^^^^^^^^^^^^^^
  File "C:\Users\Admin\AppData\Local\Programs\Python\Python311\Lib\json\encoder.py", line 258, in iterencode
    return _iterencode(o, 0)
           ^^^^^^^^^^^^^^^^^
  File "C:\Users\Admin\Documents\Banxware\balances-and-transactions-api\venv\Lib\site-packages\django\core\serializers\json.py", line 106, in default
    return super().default(o)
           ^^^^^^^^^^^^^^^^^^
  File "C:\Users\Admin\AppData\Local\Programs\Python\Python311\Lib\json\encoder.py", line 180, in default
    raise TypeError(f'Object of type {o.__class__.__name__} '
TypeError: Object of type HbalancesSerializer is not JSON serializable
ERROR 2023-09-13 22:47:14,290 django.server Thread-1 (process_request_thread) 6772 basehttp basehttp.py 212 django.server log_message 5940 "GET /balances HTTP/1.1" 500 138822
ERROR 2023-09-13 22:47:36,181 django.request Thread-1 (process_request_thread) 5300 log log.py 241 django.request log_response 20336 Internal Server Error: /balances
Traceback (most recent call last):
  File "C:\Users\Admin\Documents\Banxware\balances-and-transactions-api\venv\Lib\site-packages\django\core\handlers\exception.py", line 55, in inner
    response = get_response(request)
               ^^^^^^^^^^^^^^^^^^^^^
  File "C:\Users\Admin\Documents\Banxware\balances-and-transactions-api\venv\Lib\site-packages\django\core\handlers\base.py", line 197, in _get_response
    response = wrapped_callback(request, *callback_args, **callback_kwargs)
               ^^^^^^^^^^^^^^^^^^^^^^^^^^^^^^^^^^^^^^^^^^^^^^^^^^^^^^^^^^^^
  File "C:\Users\Admin\Documents\Banxware\balances-and-transactions-api\venv\Lib\site-packages\django\views\decorators\csrf.py", line 56, in wrapper_view
    return view_func(*args, **kwargs)
           ^^^^^^^^^^^^^^^^^^^^^^^^^^
  File "C:\Users\Admin\Documents\Banxware\balances-and-transactions-api\venv\Lib\site-packages\django\views\generic\base.py", line 104, in view
    return self.dispatch(request, *args, **kwargs)
           ^^^^^^^^^^^^^^^^^^^^^^^^^^^^^^^^^^^^^^^
  File "C:\Users\Admin\Documents\Banxware\balances-and-transactions-api\venv\Lib\site-packages\rest_framework\views.py", line 509, in dispatch
    response = self.handle_exception(exc)
               ^^^^^^^^^^^^^^^^^^^^^^^^^^
  File "C:\Users\Admin\Documents\Banxware\balances-and-transactions-api\venv\Lib\site-packages\rest_framework\views.py", line 469, in handle_exception
    self.raise_uncaught_exception(exc)
  File "C:\Users\Admin\Documents\Banxware\balances-and-transactions-api\venv\Lib\site-packages\rest_framework\views.py", line 480, in raise_uncaught_exception
    raise exc
  File "C:\Users\Admin\Documents\Banxware\balances-and-transactions-api\venv\Lib\site-packages\rest_framework\views.py", line 506, in dispatch
    response = handler(request, *args, **kwargs)
               ^^^^^^^^^^^^^^^^^^^^^^^^^^^^^^^^^
  File "C:\Users\Admin\Documents\Banxware\balances-and-transactions-api\venv\Lib\site-packages\rest_framework\generics.py", line 199, in get
    return self.list(request, *args, **kwargs)
           ^^^^^^^^^^^^^^^^^^^^^^^^^^^^^^^^^^^
  File "C:\Users\Admin\Documents\Banxware\balances-and-transactions-api\venv\Lib\site-packages\rest_framework\mixins.py", line 46, in list
    return Response(serializer.data)
                    ^^^^^^^^^^^^^^^
  File "C:\Users\Admin\Documents\Banxware\balances-and-transactions-api\venv\Lib\site-packages\rest_framework\serializers.py", line 768, in data
    ret = super().data
          ^^^^^^^^^^^^
  File "C:\Users\Admin\Documents\Banxware\balances-and-transactions-api\venv\Lib\site-packages\rest_framework\serializers.py", line 253, in data
    self._data = self.to_representation(self.instance)
                 ^^^^^^^^^^^^^^^^^^^^^^^^^^^^^^^^^^^^^
  File "C:\Users\Admin\Documents\Banxware\balances-and-transactions-api\venv\Lib\site-packages\rest_framework\serializers.py", line 686, in to_representation
    return [
           ^
  File "C:\Users\Admin\Documents\Banxware\balances-and-transactions-api\venv\Lib\site-packages\rest_framework\serializers.py", line 686, in <listcomp>
    return [
           ^
  File "C:\Users\Admin\Documents\Banxware\balances-and-transactions-api\venv\Lib\site-packages\rest_framework\serializers.py", line 538, in __iter__
    yield self[field.field_name]
          ~~~~^^^^^^^^^^^^^^^^^^
  File "C:\Users\Admin\Documents\Banxware\balances-and-transactions-api\venv\Lib\site-packages\rest_framework\serializers.py", line 542, in __getitem__
    value = self.data.get(key)
            ^^^^^^^^^
  File "C:\Users\Admin\Documents\Banxware\balances-and-transactions-api\venv\Lib\site-packages\rest_framework\serializers.py", line 555, in data
    ret = super().data
          ^^^^^^^^^^^^
  File "C:\Users\Admin\Documents\Banxware\balances-and-transactions-api\venv\Lib\site-packages\rest_framework\serializers.py", line 249, in data
    raise AssertionError(msg)
AssertionError: When a serializer is passed a `data` keyword argument you must call `.is_valid()` before attempting to access the serialized `.data` representation.
You should either call `.is_valid()` first, or access `.initial_data` instead.
ERROR 2023-09-13 22:47:36,192 django.server Thread-1 (process_request_thread) 5300 basehttp basehttp.py 212 django.server log_message 20336 "GET /balances HTTP/1.1" 500 145353
ERROR 2023-09-13 22:49:03,447 django.request Thread-1 (process_request_thread) 19876 log log.py 241 django.request log_response 10120 Internal Server Error: /balances
Traceback (most recent call last):
  File "C:\Users\Admin\Documents\Banxware\balances-and-transactions-api\venv\Lib\site-packages\django\core\handlers\exception.py", line 55, in inner
    response = get_response(request)
               ^^^^^^^^^^^^^^^^^^^^^
  File "C:\Users\Admin\Documents\Banxware\balances-and-transactions-api\venv\Lib\site-packages\django\utils\deprecation.py", line 136, in __call__
    response = self.process_response(request, response)
               ^^^^^^^^^^^^^^^^^^^^^^^^^^^^^^^^^^^^^^^^
  File "C:\Users\Admin\Documents\Banxware\balances-and-transactions-api\venv\Lib\site-packages\django\middleware\clickjacking.py", line 34, in process_response
    response.headers["X-Frame-Options"] = self.get_xframe_options_value(
    ^^^^^^^^^^^^^^^^
AttributeError: 'dict' object has no attribute 'headers'
ERROR 2023-09-13 22:49:03,451 django.server Thread-1 (process_request_thread) 19876 basehttp basehttp.py 212 django.server log_message 10120 "GET /balances HTTP/1.1" 500 72065
WARNING 2023-09-13 23:32:25,690 django.request Thread-1 (process_request_thread) 10916 log log.py 241 django.request log_response 21332 Not Found: /
WARNING 2023-09-13 23:32:25,692 django.server Thread-1 (process_request_thread) 10916 basehttp basehttp.py 212 django.server log_message 21332 "GET / HTTP/1.1" 404 2765
WARNING 2023-09-13 23:32:25,825 django.request Thread-1 (process_request_thread) 10916 log log.py 241 django.request log_response 21332 Not Found: /favicon.ico
WARNING 2023-09-13 23:32:25,827 django.server Thread-1 (process_request_thread) 10916 basehttp basehttp.py 212 django.server log_message 21332 "GET /favicon.ico HTTP/1.1" 404 2816
WARNING 2023-09-13 23:32:27,559 django.request Thread-1 (process_request_thread) 10916 log log.py 241 django.request log_response 21332 Not Found: /
WARNING 2023-09-13 23:32:27,560 django.server Thread-1 (process_request_thread) 10916 basehttp basehttp.py 212 django.server log_message 21332 "GET / HTTP/1.1" 404 2765
